internal/semcheck/testdata/semantics.txt
semantics 3
# The behaviour fingerprint. See docs/SEMANTICS-VERSION.md §5.
# scenario/pos kind command | verdict | T[trades] E[events] | state last mark bid ask counters | digest

== fifo (fifo, stp=CANCEL_NEWEST, maxOrders=100000, shard=0)
fifo/0000 SUBMIT      u3 S L 98x9 GTC+g1       | NEW                          | T[] E[ACCEPTED#1/NEW/0] | OPEN last=0 mark=0 bid=- ask=98:9 n=1 oid=1 tid=0 eid=1 | 7f166b16bfe9d4fa
fifo/0001 SUBMIT      u3 S L 104x6 GTC         | NEW                          | T[] E[ACCEPTED#2/NEW/0] | OPEN last=0 mark=0 bid=- ask=98:9 n=2 oid=2 tid=0 eid=2 | 66a120aecf263704
fifo/0002 SUBMIT      u2 S L 104x5 FOK+CANCEL_BOTH | REJECTED:FOK_CANNOT_FILL     | T[] E[REJECTED#3/FOK_CANNOT_FILL/REJECTED/0] | OPEN last=0 mark=0 bid=- ask=98:9 n=2 oid=3 tid=0 eid=3 | 139207a5e90ec947
fifo/0003 SUBMIT      u2 B L 102x5 FOK         | FILLED                       | T[1:98x5 b4 s1 m1 t4 B seq1] E[ACCEPTED#4/FILLED/5 TRADE#4/98x5] | OPEN last=98 mark=0 bid=- ask=98:4 n=2 oid=4 tid=1 eid=5 | 39b012e27657c992
fifo/0004 SUBMIT      u2 B L 101x5 IOC+CANCEL_NEWEST | CANCELLED                    | T[2:98x4 b5 s1 m1 t5 B seq2] E[ACCEPTED#5/CANCELLED/4 TRADE#5/98x4 CANCELED#5/CANCELLED/4] | OPEN last=98 mark=0 bid=- ask=104:6 n=1 oid=5 tid=2 eid=8 | a6a950f8e51b1f94
fifo/0005 REDUCE      u0 <-3 to 2              | REJECTED:ORDER_NOT_FOUND     | T[] E[] | OPEN last=98 mark=0 bid=- ask=104:6 n=1 oid=5 tid=2 eid=8 | a6a950f8e51b1f94
fifo/0006 SUBMIT      u2 B L 101x5 FOK         | REJECTED:FOK_CANNOT_FILL     | T[] E[REJECTED#6/FOK_CANNOT_FILL/REJECTED/0] | OPEN last=98 mark=0 bid=- ask=104:6 n=1 oid=6 tid=2 eid=9 | b0d83bbfa614bf53
fifo/0007 CANCEL      u2 <-2                   | REJECTED:ORDER_NOT_FOUND     | T[] E[] | OPEN last=98 mark=0 bid=- ask=104:6 n=1 oid=6 tid=2 eid=9 | b0d83bbfa614bf53
fifo/0008 REPLACE     u2 S L 99x3 GTC <-3      | REJECTED:ORDER_NOT_FOUND     | T[] E[] | OPEN last=98 mark=0 bid=- ask=104:6 n=1 oid=6 tid=2 eid=9 | b0d83bbfa614bf53
fifo/0009 SUBMIT      u3 S L 98x7 GTC+CANCEL_BOTH+priv | NEW                          | T[] E[ACCEPTED#7/NEW/0] | OPEN last=98 mark=0 bid=- ask=98:7 n=2 oid=7 tid=2 eid=10 | f6fc7df19922ae79
fifo/0010 CANCEL      u2 <-8                   | REJECTED:ORDER_NOT_FOUND     | T[] E[] | OPEN last=98 mark=0 bid=- ask=98:7 n=2 oid=7 tid=2 eid=10 | f6fc7df19922ae79
fifo/0011 SUBMIT      u3 S L 100x3 GTC+CANCEL_OLDEST | NEW                          | T[] E[ACCEPTED#8/NEW/0] | OPEN last=98 mark=0 bid=- ask=98:7 n=3 oid=8 tid=2 eid=11 | 0ddef1a58a1b9e9a
fifo/0012 SUBMIT      u3 S L 101x4 IOC+DECREMENT+g1 | CANCELLED                    | T[] E[ACCEPTED#9/CANCELLED/0 CANCELED#9/CANCELLED/0] | OPEN last=98 mark=0 bid=- ask=98:7 n=3 oid=9 tid=2 eid=13 | 3c9238dd226ef09c
fifo/0013 SUBMIT      u3 B L 100x7 GTC         | CANCELLED                    | T[] E[ACCEPTED#10/CANCELLED/0 CANCELED#10/CANCELLED/0] | OPEN last=98 mark=0 bid=- ask=98:7 n=3 oid=10 tid=2 eid=15 | fbab43ffaed8f541
fifo/0014 SUBMIT      u2 B L 100x5 FOK         | FILLED                       | T[3:98x5 b11 s7 m7 t11 B seq3] E[ACCEPTED#11/FILLED/5 TRADE#11/98x5] | OPEN last=98 mark=0 bid=- ask=98:2 n=3 oid=11 tid=3 eid=17 | 2db1aacb86674fc0
fifo/0015 SUBMIT      u2 S L 103x5 GTC+DECREMENT | NEW                          | T[] E[ACCEPTED#12/NEW/0] | OPEN last=98 mark=0 bid=- ask=98:2 n=4 oid=12 tid=3 eid=18 | 04bad485165352a0
fifo/0016 REDUCE      u3 <-10 to 7             | REJECTED:ORDER_NOT_FOUND     | T[] E[] | OPEN last=98 mark=0 bid=- ask=98:2 n=4 oid=12 tid=3 eid=18 | 04bad485165352a0
fifo/0017 CANCEL_ONLY                          | OK                           | T[] E[CANCEL_ONLY#0] | CANCEL_ONLY last=98 mark=0 bid=- ask=98:2 n=4 oid=12 tid=3 eid=19 | d58d9a31887e727a
fifo/0018 REDUCE      u1 <-4 to 1              | REJECTED:ORDER_NOT_FOUND     | T[] E[] | CANCEL_ONLY last=98 mark=0 bid=- ask=98:2 n=4 oid=12 tid=3 eid=19 | d58d9a31887e727a
fifo/0019 SUBMIT      u3 S L 100x1 GTC         | REJECTED:NEW_ORDERS_HALTED   | T[] E[REJECTED#13/NEW_ORDERS_HALTED/REJECTED/0] | CANCEL_ONLY last=98 mark=0 bid=- ask=98:2 n=4 oid=13 tid=3 eid=20 | 11efbe1485eca715
fifo/0020 SUBMIT      u1 S L 99x6 GTC+CANCEL_BOTH | REJECTED:NEW_ORDERS_HALTED   | T[] E[REJECTED#14/NEW_ORDERS_HALTED/REJECTED/0] | CANCEL_ONLY last=98 mark=0 bid=- ask=98:2 n=4 oid=14 tid=3 eid=21 | 5fdd173410fb26fd
fifo/0021 CANCEL      u1 <-12                  | REJECTED:ORDER_NOT_FOUND     | T[] E[] | CANCEL_ONLY last=98 mark=0 bid=- ask=98:2 n=4 oid=14 tid=3 eid=21 | 5fdd173410fb26fd
fifo/0022 SUBMIT      u2 S L 103x3 FOK+PO+CANCEL_NEWEST | REJECTED:NEW_ORDERS_HALTED   | T[] E[REJECTED#15/NEW_ORDERS_HALTED/REJECTED/0] | CANCEL_ONLY last=98 mark=0 bid=- ask=98:2 n=4 oid=15 tid=3 eid=22 | 1c34941df7781bd1
fifo/0023 SUBMIT      u2 B L 103x7 GTC         | REJECTED:NEW_ORDERS_HALTED   | T[] E[REJECTED#16/NEW_ORDERS_HALTED/REJECTED/0] | CANCEL_ONLY last=98 mark=0 bid=- ask=98:2 n=4 oid=16 tid=3 eid=23 | 77a4c4d8e63d078b
fifo/0024 SUBMIT      u1 S L 101x9 GTC+CANCEL_OLDEST+g1 | REJECTED:NEW_ORDERS_HALTED   | T[] E[REJECTED#17/NEW_ORDERS_HALTED/REJECTED/0] | CANCEL_ONLY last=98 mark=0 bid=- ask=98:2 n=4 oid=17 tid=3 eid=24 | 81efbe61a83d540e
fifo/0025 SUBMIT      u2 S L 98x8 GTC+CANCEL_NEWEST | REJECTED:NEW_ORDERS_HALTED   | T[] E[REJECTED#18/NEW_ORDERS_HALTED/REJECTED/0] | CANCEL_ONLY last=98 mark=0 bid=- ask=98:2 n=4 oid=18 tid=3 eid=25 | aadf49ffeecc73fe
fifo/0026 SUBMIT      u3 S L 100x7 GTC         | REJECTED:NEW_ORDERS_HALTED   | T[] E[REJECTED#19/NEW_ORDERS_HALTED/REJECTED/0] | CANCEL_ONLY last=98 mark=0 bid=- ask=98:2 n=4 oid=19 tid=3 eid=26 | 17d57dda3d63f5f9
fifo/0027 SUBMIT      u0 S M 99x7 GTC          | REJECTED:NEW_ORDERS_HALTED   | T[] E[REJECTED#20/NEW_ORDERS_HALTED/REJECTED/0] | CANCEL_ONLY last=98 mark=0 bid=- ask=98:2 n=4 oid=20 tid=3 eid=27 | 55afbc0763a65262
fifo/0028 CANCEL      u0 <-11                  | REJECTED:ORDER_NOT_FOUND     | T[] E[] | CANCEL_ONLY last=98 mark=0 bid=- ask=98:2 n=4 oid=20 tid=3 eid=27 | 55afbc0763a65262
fifo/0029 CANCEL      u2 <-11                  | REJECTED:ORDER_NOT_FOUND     | T[] E[] | CANCEL_ONLY last=98 mark=0 bid=- ask=98:2 n=4 oid=20 tid=3 eid=27 | 55afbc0763a65262
fifo/0030 SUBMIT      u3 B L 104x9 IOC         | REJECTED:NEW_ORDERS_HALTED   | T[] E[REJECTED#21/NEW_ORDERS_HALTED/REJECTED/0] | CANCEL_ONLY last=98 mark=0 bid=- ask=98:2 n=4 oid=21 tid=3 eid=28 | 72f26b3d7742bd0a
fifo/0031 REDUCE      u3 <-9 to 5              | REJECTED:INVALID_QUANTITY    | T[] E[] | CANCEL_ONLY last=98 mark=0 bid=- ask=98:2 n=4 oid=21 tid=3 eid=28 | 72f26b3d7742bd0a
fifo/0032 REPLACE     u2 S M 103x1 GTC+CANCEL_OLDEST <-21 | REJECTED:ORDER_NOT_FOUND     | T[] E[] | CANCEL_ONLY last=98 mark=0 bid=- ask=98:2 n=4 oid=21 tid=3 eid=28 | 72f26b3d7742bd0a
fifo/0033 SUBMIT      u1 S L 101x9 GTC+ALLOW   | REJECTED:NEW_ORDERS_HALTED   | T[] E[REJECTED#22/NEW_ORDERS_HALTED/REJECTED/0] | CANCEL_ONLY last=98 mark=0 bid=- ask=98:2 n=4 oid=22 tid=3 eid=29 | 4d387f297a6ff6b3
fifo/0034 SUBMIT      u0 B L 100x2 IOC+CANCEL_NEWEST+g2 | REJECTED:NEW_ORDERS_HALTED   | T[] E[REJECTED#23/NEW_ORDERS_HALTED/REJECTED/0] | CANCEL_ONLY last=98 mark=0 bid=- ask=98:2 n=4 oid=23 tid=3 eid=30 | 08c2fb2be15d9c05
fifo/0035 SUBMIT      u3 B L 102x6 GTC         | REJECTED:NEW_ORDERS_HALTED   | T[] E[REJECTED#24/NEW_ORDERS_HALTED/REJECTED/0] | CANCEL_ONLY last=98 mark=0 bid=- ask=98:2 n=4 oid=24 tid=3 eid=31 | dc7341504f200590
fifo/0036 CANCEL_ALL  u1                       | CANCELLED n=0                | T[] E[] | CANCEL_ONLY last=98 mark=0 bid=- ask=98:2 n=4 oid=24 tid=3 eid=31 | dc7341504f200590
fifo/0037 REDUCE      u3 <-30 to 2             | REJECTED:ORDER_NOT_FOUND     | T[] E[] | CANCEL_ONLY last=98 mark=0 bid=- ask=98:2 n=4 oid=24 tid=3 eid=31 | dc7341504f200590
fifo/0038 CANCEL      u1 <-28                  | REJECTED:ORDER_NOT_FOUND     | T[] E[] | CANCEL_ONLY last=98 mark=0 bid=- ask=98:2 n=4 oid=24 tid=3 eid=31 | dc7341504f200590
fifo/0039 REPLACE     u3 S M 99x5 IOC <-35     | REJECTED:ORDER_NOT_FOUND     | T[] E[] | CANCEL_ONLY last=98 mark=0 bid=- ask=98:2 n=4 oid=24 tid=3 eid=31 | dc7341504f200590
